<?xml version="1.0" ?>
<robot name="robot_ex" xmlns:xacro="http://www.ros.org/wiki/xacro">

<xacro:include filename="$(find uwrt_mars_rover_description)/urdf/materials.xacro" />
<xacro:include filename="$(find uwrt_mars_rover_description)/urdf/robot_ex.trans" />
<xacro:include filename="$(find uwrt_mars_rover_description)/urdf/robot_ex.gazebo" />
<link name="base_link">
  <inertial>
    <origin rpy="0 0 0" xyz="0.5 0.25 0.275"/>
    <mass value="404.99999999999994"/>
    <inertia ixx="11.475" ixy="0.0" ixz="0.0" iyy="36.7875" iyz="0.0" izz="42.1875"/>
  </inertial>
  <visual>
    <origin rpy="0 0 0" xyz="0 0 0"/>
    <geometry>
      <mesh filename="package://uwrt_mars_rover_description/meshes/base_link.stl" scale="0.01 0.01 0.01"/>
    </geometry>
    <material name="silver"/>
  </visual>
  <collision>
    <origin rpy="0 0 0" xyz="0 0 0"/>
    <geometry>
      <mesh filename="package://uwrt_mars_rover_description/meshes/base_link.stl" scale="0.01 0.01 0.01"/>
    </geometry>
  </collision>
</link>

<link name="Component5_1">
  <inertial>
    <origin rpy="0 0 0" xyz="0.0 -0.037499999999999985 0.0"/>
    <mass value="9.940195505498954"/>
    <inertia ixx="0.043488" ixy="0.0" ixz="-0.0" iyy="0.077658" iyz="0.0" izz="0.043488"/>
  </inertial>
  <visual>
    <origin rpy="0 0 0" xyz="-0.2 -0.0 -0.125"/>
    <geometry>
      <mesh filename="package://uwrt_mars_rover_description/meshes/Component5_1.stl" scale="0.01 0.01 0.01"/>
    </geometry>
    <material name="silver"/>
  </visual>
  <collision>
    <origin rpy="0 0 0" xyz="-0.2 -0.0 -0.125"/>
    <geometry>
      <mesh filename="package://uwrt_mars_rover_description/meshes/Component5_1.stl" scale="0.01 0.01 0.01"/>
    </geometry>
  </collision>
</link>

<link name="Component4_1">
  <inertial>
    <origin rpy="0 0 0" xyz="0.0 0.03750000000000009 0.0"/>
    <mass value="9.940195505498954"/>
    <inertia ixx="0.043488" ixy="-0.0" ixz="-0.0" iyy="0.077658" iyz="0.0" izz="0.043488"/>
  </inertial>
  <visual>
    <origin rpy="0 0 0" xyz="-0.2 -0.5 -0.125"/>
    <geometry>
      <mesh filename="package://uwrt_mars_rover_description/meshes/Component4_1.stl" scale="0.01 0.01 0.01"/>
    </geometry>
    <material name="silver"/>
  </visual>
  <collision>
    <origin rpy="0 0 0" xyz="-0.2 -0.5 -0.125"/>
    <geometry>
      <mesh filename="package://uwrt_mars_rover_description/meshes/Component4_1.stl" scale="0.01 0.01 0.01"/>
    </geometry>
  </collision>
</link>

<link name="Component2_1">
  <inertial>
    <origin rpy="0 0 0" xyz="0.0 -0.0375 -1.3877787807814457e-17"/>
    <mass value="9.940195505498954"/>
    <inertia ixx="0.043488" ixy="0.0" ixz="-0.0" iyy="0.077658" iyz="0.0" izz="0.043488"/>
  </inertial>
  <visual>
    <origin rpy="0 0 0" xyz="-0.8 -0.0 -0.125"/>
    <geometry>
      <mesh filename="package://uwrt_mars_rover_description/meshes/Component2_1.stl" scale="0.01 0.01 0.01"/>
    </geometry>
    <material name="silver"/>
  </visual>
  <collision>
    <origin rpy="0 0 0" xyz="-0.8 -0.0 -0.125"/>
    <geometry>
      <mesh filename="package://uwrt_mars_rover_description/meshes/Component2_1.stl" scale="0.01 0.01 0.01"/>
    </geometry>
  </collision>
</link>

<link name="Component3_1">
  <inertial>
    <origin rpy="0 0 0" xyz="0.0 0.03750000000000009 -1.3877787807814457e-17"/>
    <mass value="9.940195505498954"/>
    <inertia ixx="0.043488" ixy="0.0" ixz="-0.0" iyy="0.077658" iyz="0.0" izz="0.043488"/>
  </inertial>
  <visual>
    <origin rpy="0 0 0" xyz="-0.8 -0.5 -0.125"/>
    <geometry>
      <mesh filename="package://uwrt_mars_rover_description/meshes/Component3_1.stl" scale="0.01 0.01 0.01"/>
    </geometry>
    <material name="silver"/>
  </visual>
  <collision>
    <origin rpy="0 0 0" xyz="-0.8 -0.5 -0.125"/>
    <geometry>
      <mesh filename="package://uwrt_mars_rover_description/meshes/Component3_1.stl" scale="0.01 0.01 0.01"/>
    </geometry>
  </collision>
</link>

<joint name="Rev1" type="continuous">
  <origin rpy="0 0 0" xyz="0.2 0.0 0.125"/>
  <parent link="base_link"/>
  <child link="Component5_1"/>
  <axis xyz="0.0 1.0 0.0"/>
</joint>

<joint name="Rev2" type="continuous">
  <origin rpy="0 0 0" xyz="0.2 0.5 0.125"/>
  <parent link="base_link"/>
  <child link="Component4_1"/>
  <axis xyz="0.0 1.0 0.0"/>
</joint>

<joint name="Rev3" type="continuous">
  <origin rpy="0 0 0" xyz="0.8 0.0 0.125"/>
  <parent link="base_link"/>
  <child link="Component2_1"/>
  <axis xyz="0.0 1.0 0.0"/>
</joint>

<joint name="Rev4" type="continuous">
  <origin rpy="0 0 0" xyz="0.8 0.5 0.125"/>
  <parent link="base_link"/>
  <child link="Component3_1"/>
  <axis xyz="0.0 1.0 0.0"/>
</joint>

</robot>
