<?xml version="1.0" encoding="utf-8"?>
<!-- =================================================================================== -->
<!-- |    This document was autogenerated by xacro from rover.urdf.xacro               | -->
<!-- |    EDITING THIS FILE BY HAND IS NOT RECOMMENDED                                 | -->
<!-- =================================================================================== -->
<robot name="rover" xmlns:xacro="http://www.ros.org/wiki/xacro">
  <!-- Define a default link for the world -->
  <link name="world"/>
  <!-- TODO(someshdaga): Define the model of the arm accurately
       i.e dimensions, layout, limits, efforts, meshes, materials etc -->
  <!-- m -->
  <!-- m -->
  <!-- m -->
  <!-- m -->
  <!-- m -->
  <!-- rad/s^2 -->
  <!-- m -->
  <!-- (JOINT) MOBILE BASE/WORLD -> TURNTABLE -->
  <joint name="arm_base_turntable_joint" type="fixed">
    <parent link="world"/>
    <child link="arm_turntable_link"/>
    <axis rpy="0 0 0" xyz="0 0 1"/>
    <origin rpy="0 0 0" xyz="0 0 0.025"/>
  </joint>
  <!-- (LINK) TURNTABLE -->
  <link name="arm_turntable_link">
    <inertial>
      <mass value="5"/>
      <origin rpy="0 0 0" xyz="0 0 0.025"/>
      <inertia ixx="0.0135416666667" ixy="0" ixz="0" iyy="0.025" iyz="0" izz="0.0135416666667"/>
    </inertial>
    <visual>
      <origin rpy="0 0 0" xyz="0 0 0.025"/>
      <geometry>
        <cylinder length="0.05" radius="0.1"/>
      </geometry>
    </visual>
    <collision>
      <origin rpy="0 0 0" xyz="0 0 0.025"/>
      <geometry>
        <cylinder length="0.05" radius="0.1"/>
      </geometry>
    </collision>
  </link>
  <!-- (JOINT) TURNTABLE -> SHOULDER REVOLUTE LINK -->
  <joint name="arm_shoulder_joint" type="revolute">
    <parent link="arm_turntable_link"/>
    <child link="arm_shoulder_revolute_link"/>
    <origin rpy="0 0 0" xyz="0 0 0.075"/>
    <axis xyz="0 1 0"/>
    <limit effort="75" lower="-1.308996939" upper="-0.261799387799" velocity="1.0"/>
  </joint>
  <!-- (LINK) SHOULDER_REVOLUTE_LINK -->
  <link name="arm_shoulder_revolute_link">
    <inertial>
      <mass value="1.0"/>
      <origin rpy="0 0 0" xyz="0 0 0.135"/>
      <inertia ixx="0.00628333333333" ixy="0" ixz="0" iyy="0.00690833333333" iyz="0" izz="0.00104166666667"/>
    </inertial>
    <visual>
      <origin rpy="0 0 0" xyz="0 0 0.135"/>
      <geometry>
        <box size="0.1                      0.05                      0.27"/>
      </geometry>
    </visual>
    <collision>
      <origin rpy="0 0 0" xyz="0 0 0.135"/>
      <geometry>
        <box size="0.1                      0.05                      0.27"/>
      </geometry>
    </collision>
  </link>
  <!-- (JOINT) SHOULDER->BICEP (NOT ACTUATED) -->
  <joint name="arm_shoulder_bicep_joint" type="fixed">
    <parent link="arm_shoulder_revolute_link"/>
    <child link="arm_bicep_link"/>
    <origin rpy="0 2.09439510239 0" xyz="0 0 0.32"/>
  </joint>
  <!-- (LINK) BICEP -->
  <link name="arm_bicep_link">
    <inertial>
      <mass value="3.0"/>
      <origin rpy="0 0 0" xyz="0 0 0.2"/>
      <inertia ixx="0.040625" ixy="0" ixz="0" iyy="0.0425" iyz="0" izz="0.003125"/>
    </inertial>
    <visual>
      <origin rpy="0 0 0" xyz="0 0 0.2"/>
      <geometry>
        <box size="0.1                      0.05                      0.4"/>
      </geometry>
    </visual>
    <collision>
      <origin rpy="0 0 0" xyz="0 0 0.2"/>
      <geometry>
        <box size="0.1                      0.05                      0.4"/>
      </geometry>
    </collision>
  </link>
  <!-- (JOINT) ELBOW (BICEP->FOREARM) -->
  <joint name="arm_elbow_joint" type="revolute">
    <parent link="arm_bicep_link"/>
    <child link="arm_forearm_link"/>
    <origin rpy="0 -2.09439510239 0" xyz="0 0 0.45"/>
    <axis xyz="0 1 0"/>
    <limit effort="75" lower="0.0" upper="1.3962634016" velocity="1.0"/>
  </joint>
  <!-- (LINK) FOREARM -->
  <link name="arm_forearm_link">
    <inertial>
      <mass value="3.0"/>
      <origin rpy="0 0 0" xyz="0 0 0.225"/>
      <inertia ixx="0.05125" ixy="0" ixz="0" iyy="0.053125" iyz="0" izz="0.003125"/>
    </inertial>
    <visual>
      <origin rpy="0 0 0" xyz="0 0 0.225"/>
      <geometry>
        <box size="0.1                      0.05                      0.45"/>
      </geometry>
    </visual>
    <collision>
      <origin rpy="0 0 0" xyz="0 0 0.225"/>
      <geometry>
        <box size="0.1                      0.05                      0.45"/>
      </geometry>
    </collision>
  </link>
  <!-- (JOINT) WRIST [ROLL] -->
  <joint name="arm_wrist_roll_joint" type="revolute">
    <parent link="arm_forearm_link"/>
    <child link="arm_wrist_link"/>
    <origin rpy="0 0 0" xyz="0 0 0.46"/>
    <axis xyz="0 0 1"/>
    <limit effort="75" lower="-2.35619449019" upper="2.35619449019" velocity="1.0"/>
  </joint>
  <!-- (LINK) FAKE WRIST
         (Virtual link break differential transmission into 2 simple transmissions) -->
  <link name="arm_wrist_link">
    <inertial>
      <mass value="0.25"/>
      <origin rpy="0 0 0" xyz="0 0 0"/>
      <inertia ixx="5.41666666667e-05" ixy="0" ixz="0" iyy="5.41666666667e-05" iyz="0" izz="0.000104166666667"/>
    </inertial>
    <visual>
      <origin rpy="0 0 0" xyz="0 0 0"/>
      <geometry>
        <box size="0.05                      0.05                      0.01"/>
      </geometry>
    </visual>
    <collision>
      <origin rpy="0 0 0" xyz="0 0 0"/>
      <geometry>
        <box size="0.05                      0.05                      0.01"/>
      </geometry>
    </collision>
  </link>
  <!-- (JOINT) WRIST [PITCH] -->
  <joint name="arm_wrist_pitch_joint" type="revolute">
    <parent link="arm_wrist_link"/>
    <child link="arm_claw_link"/>
    <origin rpy="0 0 0" xyz="0 0 0.01"/>
    <axis xyz="0 1 0"/>
    <limit effort="75" lower="-1.308996939" upper="1.308996939" velocity="1.0"/>
  </joint>
  <!-- (LINK) CLAW -->
  <link name="arm_claw_link" type="fixed">
    <inertial>
      <mass value="0.5"/>
      <origin rpy="0 0 0" xyz="0 0 0.05"/>
      <inertia ixx="0.000520833333333" ixy="0" ixz="0" iyy="0.000520833333333" iyz="0" izz="0.000208333333333"/>
    </inertial>
    <visual>
      <origin rpy="0 0 0" xyz="0 0 0.05"/>
      <geometry>
        <box size="0.05 0.05 0.1"/>
      </geometry>
    </visual>
    <collision>
      <origin rpy="0 0 0" xyz="0 0 0.025"/>
      <geometry>
        <box size="0.05                      0.05                      0.1"/>
      </geometry>
    </collision>
  </link>
  <gazebo>
    <plugin filename="libgazebo_uwrt_arm_hw.so" name="uwrt_arm_hw">
      <robotNamespace>/</robotNamespace>
    </plugin>
  </gazebo>
  <gazebo reference="arm_turntable_link">
    <static>false</static>
    <gravity>true</gravity>
    <selfCollide>true</selfCollide>
  </gazebo>
  <gazebo reference="arm_shoulder_revolute_link">
    <static>false</static>
    <gravity>true</gravity>
    <selfCollide>true</selfCollide>
  </gazebo>
  <gazebo reference="arm_bicep_link">
    <static>false</static>
    <gravity>true</gravity>
    <selfCollide>true</selfCollide>
  </gazebo>
  <gazebo reference="arm_forearm_link">
    <static>false</static>
    <gravity>true</gravity>
    <selfCollide>true</selfCollide>
  </gazebo>
  <gazebo reference="arm_wrist_link">
    <static>false</static>
    <gravity>true</gravity>
    <selfCollide>true</selfCollide>
  </gazebo>
  <gazebo reference="arm_claw_link">
    <static>false</static>
    <gravity>true</gravity>
    <selfCollide>true</selfCollide>
  </gazebo>
  <!-- SHOULDER -->
  <transmission name="arm_shoulder_trans">
    <type>transmission_interface/SimpleTransmission</type>
    <joint name="arm_shoulder_joint">
      <hardwareInterface>hardware_interface/PositionJointInterface</hardwareInterface>
    </joint>
    <actuator name="arm_shoulder_motor">
      <mechanicalReduction>1</mechanicalReduction>
    </actuator>
  </transmission>
  <!-- ELBOW -->
  <transmission name="arm_elbow_trans">
    <type>transmission_interface/SimpleTransmission</type>
    <joint name="arm_elbow_joint">
      <hardwareInterface>hardware_interface/PositionJointInterface</hardwareInterface>
    </joint>
    <actuator name="arm_elbow_motor">
      <mechanicalReduction>1</mechanicalReduction>
    </actuator>
  </transmission>
  <!-- WRIST -->
  <transmission name="arm_wrist_roll_trans">
    <type>transmission_interface/SimpleTransmission</type>
    <joint name="arm_wrist_roll_joint">
      <hardwareInterface>hardware_interface/PositionJointInterface</hardwareInterface>
    </joint>
    <actuator name="arm_wrist_roll_motor">
      <mechanicalReduction>1</mechanicalReduction>
    </actuator>
  </transmission>
  <transmission name="arm_wrist_pitch_trans">
    <type>transmission_interface/SimpleTransmission</type>
    <joint name="arm_wrist_pitch_joint">
      <hardwareInterface>hardware_interface/PositionJointInterface</hardwareInterface>
    </joint>
    <actuator name="arm_wrist_pitch_motor">
      <mechanicalReduction>1</mechanicalReduction>
    </actuator>
  </transmission>
</robot>
