<?xml version="1.0" ?>
<!-- =================================================================================== -->
<!-- |    This document was autogenerated by xacro from drivetrain.urdf.xacro          | -->
<!-- |    EDITING THIS FILE BY HAND IS NOT RECOMMENDED                                 | -->
<!-- =================================================================================== -->
<robot name="drivetrain">
  <ros2_control name="right_front_wheel_actuator" type="actuator">
    <hardware>
      <plugin>gazebo_ros2_control/GazeboSystem</plugin>
    </hardware>
    <joint name="right_front_wheel_joint">
      <command_interface name="velocity">
        <param name="min">-14.660765716752369</param>
        <param name="max">14.660765716752369</param>
      </command_interface>
      <state_interface name="position"/>
      <state_interface name="velocity"/>
      <state_interface name="iq_current"/>
      <!-- TODO: acceleration, torque? -->
    </joint>
    <transmission name="transmission1">
      <!--  TODO: These are not actually parsed by ros2control yet: https://github.com/ros-controls/ros2_control/issues/32, https://github.com/ros-controls/ros2_control/issues/599 -->
      <plugin>transmission_interface/SimpleTransmission</plugin>
      <joint name="right_front_wheel_joint" role="joint1">
        <mechanical_reduction>0.04</mechanical_reduction>
      </joint>
    </transmission>
  </ros2_control>
  <ros2_control name="right_middle_wheel_actuator" type="actuator">
    <hardware>
      <plugin>gazebo_ros2_control/GazeboSystem</plugin>
    </hardware>
    <joint name="right_middle_wheel_joint">
      <command_interface name="velocity">
        <param name="min">-14.660765716752369</param>
        <param name="max">14.660765716752369</param>
      </command_interface>
      <state_interface name="position"/>
      <state_interface name="velocity"/>
      <state_interface name="iq_current"/>
      <!-- TODO: acceleration, torque? -->
    </joint>
    <transmission name="transmission1">
      <!--  TODO: These are not actually parsed by ros2control yet: https://github.com/ros-controls/ros2_control/issues/32, https://github.com/ros-controls/ros2_control/issues/599 -->
      <plugin>transmission_interface/SimpleTransmission</plugin>
      <joint name="right_middle_wheel_joint" role="joint1">
        <mechanical_reduction>0.04</mechanical_reduction>
      </joint>
    </transmission>
  </ros2_control>
  <ros2_control name="right_back_wheel_actuator" type="actuator">
    <hardware>
      <plugin>gazebo_ros2_control/GazeboSystem</plugin>
    </hardware>
    <joint name="right_back_wheel_joint">
      <command_interface name="velocity">
        <param name="min">-14.660765716752369</param>
        <param name="max">14.660765716752369</param>
      </command_interface>
      <state_interface name="position"/>
      <state_interface name="velocity"/>
      <state_interface name="iq_current"/>
      <!-- TODO: acceleration, torque? -->
    </joint>
    <transmission name="transmission1">
      <!--  TODO: These are not actually parsed by ros2control yet: https://github.com/ros-controls/ros2_control/issues/32, https://github.com/ros-controls/ros2_control/issues/599 -->
      <plugin>transmission_interface/SimpleTransmission</plugin>
      <joint name="right_back_wheel_joint" role="joint1">
        <mechanical_reduction>0.04</mechanical_reduction>
      </joint>
    </transmission>
  </ros2_control>
  <ros2_control name="left_front_wheel_actuator" type="actuator">
    <hardware>
      <plugin>gazebo_ros2_control/GazeboSystem</plugin>
    </hardware>
    <joint name="left_front_wheel_joint">
      <command_interface name="velocity">
        <param name="min">-14.660765716752369</param>
        <param name="max">14.660765716752369</param>
      </command_interface>
      <state_interface name="position"/>
      <state_interface name="velocity"/>
      <state_interface name="iq_current"/>
      <!-- TODO: acceleration, torque? -->
    </joint>
    <transmission name="transmission1">
      <!--  TODO: These are not actually parsed by ros2control yet: https://github.com/ros-controls/ros2_control/issues/32, https://github.com/ros-controls/ros2_control/issues/599 -->
      <plugin>transmission_interface/SimpleTransmission</plugin>
      <joint name="left_front_wheel_joint" role="joint1">
        <mechanical_reduction>0.04</mechanical_reduction>
      </joint>
    </transmission>
  </ros2_control>
  <ros2_control name="left_middle_wheel_actuator" type="actuator">
    <hardware>
      <plugin>gazebo_ros2_control/GazeboSystem</plugin>
    </hardware>
    <joint name="left_middle_wheel_joint">
      <command_interface name="velocity">
        <param name="min">-14.660765716752369</param>
        <param name="max">14.660765716752369</param>
      </command_interface>
      <state_interface name="position"/>
      <state_interface name="velocity"/>
      <state_interface name="iq_current"/>
      <!-- TODO: acceleration, torque? -->
    </joint>
    <transmission name="transmission1">
      <!--  TODO: These are not actually parsed by ros2control yet: https://github.com/ros-controls/ros2_control/issues/32, https://github.com/ros-controls/ros2_control/issues/599 -->
      <plugin>transmission_interface/SimpleTransmission</plugin>
      <joint name="left_middle_wheel_joint" role="joint1">
        <mechanical_reduction>0.04</mechanical_reduction>
      </joint>
    </transmission>
  </ros2_control>
  <ros2_control name="left_back_wheel_actuator" type="actuator">
    <hardware>
      <plugin>gazebo_ros2_control/GazeboSystem</plugin>
    </hardware>
    <joint name="left_back_wheel_joint">
      <command_interface name="velocity">
        <param name="min">-14.660765716752369</param>
        <param name="max">14.660765716752369</param>
      </command_interface>
      <state_interface name="position"/>
      <state_interface name="velocity"/>
      <state_interface name="iq_current"/>
      <!-- TODO: acceleration, torque? -->
    </joint>
    <transmission name="transmission1">
      <!--  TODO: These are not actually parsed by ros2control yet: https://github.com/ros-controls/ros2_control/issues/32, https://github.com/ros-controls/ros2_control/issues/599 -->
      <plugin>transmission_interface/SimpleTransmission</plugin>
      <joint name="left_back_wheel_joint" role="joint1">
        <mechanical_reduction>0.04</mechanical_reduction>
      </joint>
    </transmission>
  </ros2_control>
  <!-- Gazebo plugins -->
  <gazebo reference="world">
    </gazebo>
  <gazebo>
    <plugin filename="libgazebo_ros2_control.so" name="gazebo_ros2_control">
      <robot_param>robot_description</robot_param>
      <robot_param_node>robot_state_publisher</robot_param_node>
      <robot_sim_type>gazebo_ros2_control/DefaultRobotHWSim</robot_sim_type>
      <parameters>/workspaces/ROS-DOCKER/ros2_ws/install/uwrt_mars_rover_drivetrain_description/share/uwrt_mars_rover_drivetrain_description/config/drivetrain_controllers.yaml</parameters>
    </plugin>
  </gazebo>
  <link name="base_link"/>
  <joint name="base_link_to_chassis" type="fixed">
    <parent link="base_link"/>
    <child link="chassis"/>
    <origin rpy="0 0 0" xyz="0 0 0.15"/>
  </joint>
  <link name="chassis">
    <visual>
      <geometry>
        <box size="1.17 0.807 0.2"/>
      </geometry>
    </visual>
    <collision>
      <geometry>
        <box size="1.17 0.807 0.2"/>
      </geometry>
    </collision>
    <inertial>
      <mass value="5"/>
      <inertia ixx="1e-3" ixy="0.0" ixz="0.0" iyy="1e-3" iyz="0.0" izz="1e-3"/>
    </inertial>
  </link>
  <joint name="right_front_wheel_joint" type="continuous">
    <axis rpy="0 0 0" xyz="0 1 0"/>
    <parent link="chassis"/>
    <child link="right_front_wheel"/>
    <origin rpy="0 0 0" xyz="0.585 -0.49850000000000005 0"/>
  </joint>
  <link name="right_front_wheel">
    <visual>
      <origin rpy="1.5707963267948966 0 0" xyz="0 0 0"/>
      <geometry>
        <cylinder length="0.19" radius="0.15"/>
      </geometry>
    </visual>
    <collision>
      <origin rpy="1.5707963267948966 0 0" xyz="0 0 0"/>
      <geometry>
        <cylinder length="0.19" radius="0.15"/>
      </geometry>
    </collision>
    <inertial>
      <mass value="2.12"/>
      <inertia ixx="1e-3" ixy="0.0" ixz="0.0" iyy="1e-3" iyz="0.0" izz="1e-3"/>
    </inertial>
  </link>
  <joint name="right_middle_wheel_joint" type="continuous">
    <axis rpy="0 0 0" xyz="0 1 0"/>
    <parent link="chassis"/>
    <child link="right_middle_wheel"/>
    <origin rpy="0 0 0" xyz="0 -0.49850000000000005 0"/>
  </joint>
  <link name="right_middle_wheel">
    <visual>
      <origin rpy="1.5707963267948966 0 0" xyz="0 0 0"/>
      <geometry>
        <cylinder length="0.19" radius="0.15"/>
      </geometry>
    </visual>
    <collision>
      <origin rpy="1.5707963267948966 0 0" xyz="0 0 0"/>
      <geometry>
        <cylinder length="0.19" radius="0.15"/>
      </geometry>
    </collision>
    <inertial>
      <mass value="2.12"/>
      <inertia ixx="1e-3" ixy="0.0" ixz="0.0" iyy="1e-3" iyz="0.0" izz="1e-3"/>
    </inertial>
  </link>
  <joint name="right_back_wheel_joint" type="continuous">
    <axis rpy="0 0 0" xyz="0 1 0"/>
    <parent link="chassis"/>
    <child link="right_back_wheel"/>
    <origin rpy="0 0 0" xyz="-0.585 -0.49850000000000005 0"/>
  </joint>
  <link name="right_back_wheel">
    <visual>
      <origin rpy="1.5707963267948966 0 0" xyz="0 0 0"/>
      <geometry>
        <cylinder length="0.19" radius="0.15"/>
      </geometry>
    </visual>
    <collision>
      <origin rpy="1.5707963267948966 0 0" xyz="0 0 0"/>
      <geometry>
        <cylinder length="0.19" radius="0.15"/>
      </geometry>
    </collision>
    <inertial>
      <mass value="2.12"/>
      <inertia ixx="1e-3" ixy="0.0" ixz="0.0" iyy="1e-3" iyz="0.0" izz="1e-3"/>
    </inertial>
  </link>
  <joint name="left_front_wheel_joint" type="continuous">
    <axis rpy="0 0 0" xyz="0 1 0"/>
    <parent link="chassis"/>
    <child link="left_front_wheel"/>
    <origin rpy="0 0 0" xyz="0.585 0.49850000000000005 0"/>
  </joint>
  <link name="left_front_wheel">
    <visual>
      <origin rpy="1.5707963267948966 0 0" xyz="0 0 0"/>
      <geometry>
        <cylinder length="0.19" radius="0.15"/>
      </geometry>
    </visual>
    <collision>
      <origin rpy="1.5707963267948966 0 0" xyz="0 0 0"/>
      <geometry>
        <cylinder length="0.19" radius="0.15"/>
      </geometry>
    </collision>
    <inertial>
      <mass value="2.12"/>
      <inertia ixx="1e-3" ixy="0.0" ixz="0.0" iyy="1e-3" iyz="0.0" izz="1e-3"/>
    </inertial>
  </link>
  <joint name="left_middle_wheel_joint" type="continuous">
    <axis rpy="0 0 0" xyz="0 1 0"/>
    <parent link="chassis"/>
    <child link="left_middle_wheel"/>
    <origin rpy="0 0 0" xyz="0 0.49850000000000005 0"/>
  </joint>
  <link name="left_middle_wheel">
    <visual>
      <origin rpy="1.5707963267948966 0 0" xyz="0 0 0"/>
      <geometry>
        <cylinder length="0.19" radius="0.15"/>
      </geometry>
    </visual>
    <collision>
      <origin rpy="1.5707963267948966 0 0" xyz="0 0 0"/>
      <geometry>
        <cylinder length="0.19" radius="0.15"/>
      </geometry>
    </collision>
    <inertial>
      <mass value="2.12"/>
      <inertia ixx="1e-3" ixy="0.0" ixz="0.0" iyy="1e-3" iyz="0.0" izz="1e-3"/>
    </inertial>
  </link>
  <joint name="left_back_wheel_joint" type="continuous">
    <axis rpy="0 0 0" xyz="0 1 0"/>
    <parent link="chassis"/>
    <child link="left_back_wheel"/>
    <origin rpy="0 0 0" xyz="-0.585 0.49850000000000005 0"/>
  </joint>
  <link name="left_back_wheel">
    <visual>
      <origin rpy="1.5707963267948966 0 0" xyz="0 0 0"/>
      <geometry>
        <cylinder length="0.19" radius="0.15"/>
      </geometry>
    </visual>
    <collision>
      <origin rpy="1.5707963267948966 0 0" xyz="0 0 0"/>
      <geometry>
        <cylinder length="0.19" radius="0.15"/>
      </geometry>
    </collision>
    <inertial>
      <mass value="2.12"/>
      <inertia ixx="1e-3" ixy="0.0" ixz="0.0" iyy="1e-3" iyz="0.0" izz="1e-3"/>
    </inertial>
  </link>
</robot>
